<?xml version="1.0"?>
<robot xmlns:xacro="http://ros.org/wiki/xacro">
  <xacro:include filename="$(find hdr_description)/urdf/tools/onrobot_gripper/rg6/onrobot_rg6_transmission.xacro" />
  <xacro:include filename="$(find hdr_description)/urdf/tools/onrobot_gripper/rg6/onrobot_rg6_gazebo.xacro" />
  <xacro:include filename="$(find hdr_description)/urdf/tools/onrobot_gripper/rg6/onrobot_rg6.ros2_control.xacro" />

  <xacro:macro name="outer_knuckle" params="prefix fingerprefix">
    <link name="${prefix}${fingerprefix}_outer_knuckle">
      <inertial>
        <origin xyz="0.0 0.0 0.0" rpy="0 0 0" />
        <mass value="0.05" />
        <inertia ixx="1.0E-03" ixy="1.0E-06" ixz="1.0E-06" iyy="1.0E-03" iyz="1.0E-06" izz="1.0E-03" />
      </inertial>
      <visual>
        <origin xyz="0 0 0" rpy="0 0 0" />
        <geometry>
          <mesh filename="package://hdr_description/meshes/tools/onrobot_gripper/rg6/visual/outer_knuckle.stl" />
        </geometry>
        <material name="">
          <color rgba="0.8 0.8 0.8 1" />
        </material>
      </visual>
      <collision>
        <origin xyz="0 0 0" rpy="0 0 0" />
        <geometry>
          <mesh filename="package://hdr_description/meshes/tools/onrobot_gripper/rg6/collision/outer_knuckle.stl" />
        </geometry>
      </collision>
    </link>

    <gazebo reference="${prefix}${fingerprefix}_outer_knuckle">
      <mu1>1.0</mu1>
      <mu2>1.0</mu2>
      <selfCollide>false</selfCollide>
      <material>Gazebo/White</material>
    </gazebo>
  </xacro:macro>

  <xacro:macro name="inner_knuckle" params="prefix fingerprefix">
    <link name="${prefix}${fingerprefix}_inner_knuckle">
      <inertial>
        <origin xyz="0.0 0.0 0.0" rpy="0 0 0" />
        <mass value="0.05" />
        <inertia ixx="1.0E-03" ixy="1.0E-06" ixz="1.0E-06" iyy="1.0E-03" iyz="1.0E-06" izz="1.0E-03" />
      </inertial>
      <visual>
        <origin xyz="0 0 0" rpy="0 0 0" />
        <geometry>
          <mesh filename="package://hdr_description/meshes/tools/onrobot_gripper/rg6/visual/inner_knuckle.stl" />
        </geometry>
        <material name="">
          <color rgba="0.8 0.8 0.8 1" />
        </material>
      </visual>
      <collision>
        <origin xyz="0 0 0" rpy="0 0 0" />
        <geometry>
          <mesh filename="package://hdr_description/meshes/tools/onrobot_gripper/rg6/collision/inner_knuckle.stl" />
        </geometry>
      </collision>
    </link>

    <gazebo reference="${prefix}${fingerprefix}_inner_knuckle">
      <mu1>1.0</mu1>
      <mu2>1.0</mu2>
      <selfCollide>false</selfCollide>
      <material>Gazebo/White</material>
    </gazebo>
  </xacro:macro>

  <xacro:macro name="inner_finger" params="prefix fingerprefix">
    <link name="${prefix}${fingerprefix}_inner_finger">
      <inertial>
        <origin xyz="0.0 0.0 0.0" rpy="0 0 0" />
        <mass value="0.05" />
        <inertia ixx="1.0E-03" ixy="1.0E-06" ixz="1.0E-06" iyy="1.0E-03" iyz="1.0E-06" izz="1.0E-03" />
      </inertial>
      <visual>
        <origin xyz="0 0 0" rpy="0 0 0" />
        <geometry>
          <mesh filename="package://hdr_description/meshes/tools/onrobot_gripper/rg6/visual/inner_finger.stl" />
        </geometry>
        <material name="">
          <color rgba="0.1 0.1 0.1 1" />
        </material>
      </visual>
      <collision>
        <origin xyz="0 0 0" rpy="0 0 0" />
        <geometry>
          <mesh filename="package://hdr_description/meshes/tools/onrobot_gripper/rg6/collision/inner_finger.stl" />
        </geometry>
      </collision>
    </link>

    <gazebo reference="${prefix}${fingerprefix}_inner_finger">
      <kp>1000000.0</kp>
      <kd>1.0</kd>
      <mu1>1.0</mu1>
      <mu2>1.0</mu2>
      <minDepth>0.001</minDepth>
      <selfCollide>false</selfCollide>
      <material>Gazebo/Black</material>
    </gazebo>
  </xacro:macro>

  <xacro:macro name="inner_knuckle_joint" params="prefix fingerprefix reflect">
    <joint name="${prefix}${fingerprefix}_inner_knuckle_joint" type="revolute">
      <origin xyz="0 ${reflect * -0.012720} 0.159500" rpy="0 0 ${(reflect - 1) * pi / 2}" />
      <parent link="${prefix}base_link" />
      <child link="${prefix}${fingerprefix}_inner_knuckle" />
      <axis xyz="1 0 0" />
      <limit lower="-0.628319" upper="0.628319" velocity="2.0" effort="1000" />
      <mimic joint="${prefix}finger_joint" multiplier="-1" offset="0" />
    </joint>
  </xacro:macro>

  <xacro:macro name="inner_finger_joint" params="prefix fingerprefix">
    <joint name="${prefix}${fingerprefix}_inner_finger_joint" type="revolute">
      <origin xyz="0 ${-(0.071447-0.024112)} ${0.201308-0.136813}" rpy="0 0 0" />
      <parent link="${prefix}${fingerprefix}_outer_knuckle" />
      <child link="${prefix}${fingerprefix}_inner_finger" />
      <axis xyz="1 0 0" />
      <limit lower="-0.872665" upper="0.872665" velocity="2.0" effort="1000" />
      <mimic joint="${prefix}finger_joint" multiplier="1" offset="0" />
    </joint>
  </xacro:macro>

  <xacro:include filename="$(find hdr_description)/urdf/tools/onrobot_gripper/rg6/onrobot_rg6.xacro" />

  <xacro:macro name="finger_joint" params="prefix">
    <joint name="${prefix}finger_joint" type="revolute">
      <origin xyz="0 -0.024112 0.136813" rpy="0 0 0" />
      <parent link="${prefix}base_link" />
      <child link="${prefix}left_outer_knuckle" />
      <axis xyz="-1 0 0" />
      <limit lower="-0.628319" upper="0.628319" velocity="2.0" effort="1000" />
    </joint>
    <xacro:finger_joints prefix="${prefix}" fingerprefix="left" reflect="1.0"/>
  </xacro:macro>

  <xacro:macro name="right_outer_knuckle_joint" params="prefix">
    <joint name="${prefix}right_outer_knuckle_joint" type="revolute">
      <origin xyz="0 0.024112 0.136813" rpy="0 0 ${pi}" />
      <parent link="${prefix}base_link" />
      <child link="${prefix}right_outer_knuckle" />
      <axis xyz="1 0 0" />
      <limit lower="-0.628319" upper="0.628319" velocity="2.0" effort="1000" />
      <mimic joint="${prefix}finger_joint" multiplier="-1" offset="0" />
    </joint>
    <xacro:finger_joints prefix="${prefix}" fingerprefix="right" reflect="-1.0"/>
  </xacro:macro>

  <!--
    OnRobot RG6 Gripper Macro
    Parameters:
      - prefix: joint/link name prefix
      - use_sim: enable Gazebo Sim plugin (default: false)
      - use_mock_hardware: enable mock hardware (default: false)
      - include_ros2_control: include standalone ros2_control block (default: false)
                              Set to false when gripper is part of a larger robot system
                              that defines its own ros2_control block
  -->
  <xacro:macro name="onrobot_rg6" params="prefix use_sim:=false use_mock_hardware:=false include_ros2_control:=false">
    <xacro:base_link prefix="${prefix}"/>
    <xacro:finger_links prefix="${prefix}" fingerprefix="left"/>
    <xacro:finger_links prefix="${prefix}" fingerprefix="right"/>
    <xacro:finger_joint prefix="${prefix}"/>
    <xacro:right_outer_knuckle_joint prefix="${prefix}"/>
    <xacro:onrobot_rg6_transmission prefix="${prefix}"/>
    <xacro:if value="${use_sim}">
      <xacro:onrobot_rg6_gazebo prefix="${prefix}"/>
    </xacro:if>
    <xacro:if value="${include_ros2_control}">
      <xacro:onrobot_rg6_ros2_control
        name="OnRobotRG6GripperSystem"
        prefix="${prefix}"
        use_sim="${use_sim}"
        use_mock_hardware="${use_mock_hardware}"/>
    </xacro:if>
  </xacro:macro>
</robot>
