<?xml version="1.0"?>
<robot name="hdr_robot" xmlns:xacro="http://ros.org/wiki/xacro">
  <material name="ivory">
    <color rgba="1.0 0.945 0.773 1.0" />
  </material>
  <material name="gray">
    <color rgba="0.3 0.3 0.3 1.0"/>
  </material>
  <material name="black">
    <color rgba="0.2 0.2 0.2 1.0"/>
  </material>
  <xacro:property name="mesh_scale" value="0.001" />
  <link name="base_link">
    <visual>
      <geometry>
        <mesh filename="file://$(find hdr_description)/meshes/robots/hh020/visual/base_body.stl" scale="${mesh_scale} ${mesh_scale} ${mesh_scale}"/>
      </geometry>
      <material name="ivory"/>
    </visual>
    <collision>
      <geometry>
        <mesh filename="file://$(find hdr_description)/meshes/robots/hh020/collision/base_body.stl" scale="${mesh_scale} ${mesh_scale} ${mesh_scale}"/>
      </geometry>
    </collision>
    <inertial>
      <mass value="31.2543"/>
      <origin xyz="0 0 0" rpy="0 0 0"/>
      <inertia ixx="0.4278" ixy="0" ixz="0" iyy="0.7085" iyz="0" izz="0.8249"/>
    </inertial>
  </link>
  <link name="lower_frame_link">
    <visual>
      <geometry>
        <mesh filename="file://$(find hdr_description)/meshes/robots/hh020/visual/lower_frame.stl" scale="${mesh_scale} ${mesh_scale} ${mesh_scale}"/>
      </geometry>
      <material name="ivory"/>
    </visual>
    <collision>
      <geometry>
        <mesh filename="file://$(find hdr_description)/meshes/robots/hh020/collision/lower_frame.stl" scale="${mesh_scale} ${mesh_scale} ${mesh_scale}"/>
      </geometry>
    </collision>
    <inertial>
      <mass value="44.2299"/>
      <origin xyz="0 0 0" rpy="0 0 0"/>
      <inertia ixx="1.046" ixy="0" ixz="0" iyy="1.046" iyz="0" izz="1.1643"/>
    </inertial>
  </link>
  <link name="upper_frame_link">
    <visual>
      <geometry>
        <mesh filename="file://$(find hdr_description)/meshes/robots/hh020/visual/upper_frame.stl" scale="${mesh_scale} ${mesh_scale} ${mesh_scale}"/>
      </geometry>
      <material name="ivory"/>
    </visual>
    <collision>
      <geometry>
        <mesh filename="file://$(find hdr_description)/meshes/robots/hh020/collision/upper_frame.stl" scale="${mesh_scale} ${mesh_scale} ${mesh_scale}"/>
      </geometry>
    </collision>
    <inertial>
      <mass value="22.4028"/>
      <origin xyz="0 0 0" rpy="0 0 0"/>
      <inertia ixx="1.8777" ixy="0" ixz="0" iyy="1.9502" iyz="0" izz="0.1647"/>
    </inertial>
  </link>
  <link name="arm_link">
    <visual>
      <geometry>
        <mesh filename="file://$(find hdr_description)/meshes/robots/hh020/visual/arm.stl" scale="${mesh_scale} ${mesh_scale} ${mesh_scale}"/>
      </geometry>
      <material name="ivory"/>
    </visual>
    <collision>
      <geometry>
        <mesh filename="file://$(find hdr_description)/meshes/robots/hh020/collision/arm.stl" scale="${mesh_scale} ${mesh_scale} ${mesh_scale}"/>
      </geometry>
    </collision>
    <inertial>
      <mass value="14.2656"/>
      <origin xyz="0 0 0" rpy="0 0 0"/>
      <inertia ixx="0.1905" ixy="0" ixz="0" iyy="0.2375" iyz="0" izz="0.1845"/>
    </inertial>
  </link>
  <link name="wrist_body_link">
    <visual>
      <origin xyz="-0.162 0 0" rpy="0 0 0"/>
      <geometry>
        <mesh filename="file://$(find hdr_description)/meshes/robots/hh020/visual/wrist_body.stl" scale="${mesh_scale} ${mesh_scale} ${mesh_scale}"/>
      </geometry>
      <material name="ivory"/>
    </visual>
    <collision>
      <origin xyz="-0.162 0 0" rpy="0 0 0"/>
      <geometry>
        <mesh filename="file://$(find hdr_description)/meshes/robots/hh020/collision/wrist_body.stl" scale="${mesh_scale} ${mesh_scale} ${mesh_scale}"/>
      </geometry>
    </collision>
    <inertial>
      <mass value="7.0632"/>
      <origin xyz="0 0 0" rpy="0 0 0"/>
      <inertia ixx="0.0347" ixy="0" ixz="0" iyy="0.2705" iyz="0" izz="0.281"/>
    </inertial>
  </link>
  <link name="wrist_holder_link">
    <visual>
      <origin xyz="0.00186 0 0.0022" rpy="0 0 0"/>
      <geometry>
        <mesh filename="file://$(find hdr_description)/meshes/robots/hh020/visual/wrist_holder.stl" scale="${mesh_scale} ${mesh_scale} ${mesh_scale}"/>
      </geometry>
      <material name="ivory"/>
    </visual>
    <collision>
      <origin xyz="0.00186 0 0.0022" rpy="0 0 0"/>
      <geometry>
        <mesh filename="file://$(find hdr_description)/meshes/robots/hh020/collision/wrist_holder.stl" scale="${mesh_scale} ${mesh_scale} ${mesh_scale}"/>
      </geometry>
    </collision>
    <inertial>
      <mass value="3.8171"/>
      <origin xyz="0 0 0" rpy="0 0 0"/>
      <inertia ixx="0.0087" ixy="0" ixz="0" iyy="0.0172" iyz="0" izz="0.0182"/>
    </inertial>
  </link>
  <link name="flange_link">
    <visual>
      <geometry>
        <mesh filename="file://$(find hdr_description)/meshes/robots/hh020/visual/flange.stl" scale="${mesh_scale} ${mesh_scale} ${mesh_scale}"/>
      </geometry>
      <material name="gray"/>
    </visual>
    <collision>
      <geometry>
        <mesh filename="file://$(find hdr_description)/meshes/robots/hh020/collision/flange.stl" scale="${mesh_scale} ${mesh_scale} ${mesh_scale}"/>
      </geometry>
    </collision>
    <inertial>
      <mass value="0.4672"/>
      <origin xyz="0 0 0" rpy="0 0 0"/>
      <inertia ixx="0.0002" ixy="0" ixz="0" iyy="0.0001" iyz="0" izz="0.0001"/>
    </inertial>
  </link>
  <link name="motor_s">
    <visual>
      <geometry>
        <mesh filename="file://$(find hdr_description)/meshes/robots/hh020/visual/motor_s.stl" scale="${mesh_scale} ${mesh_scale} ${mesh_scale}"/>
      </geometry>
      <material name="black"/>
    </visual>
    <collision>
      <geometry>
        <mesh filename="file://$(find hdr_description)/meshes/robots/hh020/collision/motor_s.stl" scale="${mesh_scale} ${mesh_scale} ${mesh_scale}"/>
      </geometry>
    </collision>
    <inertial>
      <mass value="0"/>
      <origin xyz="0 0 0" rpy="0 0 0"/>
      <inertia ixx="1e-6" ixy="0" ixz="0" iyy="1e-6" iyz="0" izz="1e-6"/>
    </inertial>
  </link>
  <link name="motor_h">
    <visual>
      <geometry>
        <mesh filename="file://$(find hdr_description)/meshes/robots/hh020/visual/motor_h.stl" scale="${mesh_scale} ${mesh_scale} ${mesh_scale}"/>
      </geometry>
      <material name="black"/>
    </visual>
    <collision>
      <geometry>
        <mesh filename="file://$(find hdr_description)/meshes/robots/hh020/collision/motor_h.stl" scale="${mesh_scale} ${mesh_scale} ${mesh_scale}"/>
      </geometry>
    </collision>
    <inertial>
      <mass value="0"/>
      <origin xyz="0 0 0" rpy="0 0 0"/>
      <inertia ixx="1e-6" ixy="0" ixz="0" iyy="1e-6" iyz="0" izz="1e-6"/>
    </inertial>
  </link>
  <link name="motor_v">
    <visual>
      <geometry>
        <mesh filename="file://$(find hdr_description)/meshes/robots/hh020/visual/motor_v.stl" scale="${mesh_scale} ${mesh_scale} ${mesh_scale}"/>
      </geometry>
      <material name="black"/>
    </visual>
    <collision>
      <geometry>
        <mesh filename="file://$(find hdr_description)/meshes/robots/hh020/collision/motor_v.stl" scale="${mesh_scale} ${mesh_scale} ${mesh_scale}"/>
      </geometry>
    </collision>
    <inertial>
      <mass value="0"/>
      <origin xyz="0 0 0" rpy="0 0 0"/>
      <inertia ixx="1e-6" ixy="0" ixz="0" iyy="1e-6" iyz="0" izz="1e-6"/>
    </inertial>
  </link>

  <joint name="j1" type="revolute">
    <parent link="base_link"/>
    <child link="lower_frame_link"/>
    <origin xyz="0 0 0" rpy="0 0 0"/>
    <axis xyz="0 0 1"/>
    <limit lower="-3.229" upper="3.229" effort="962.91" velocity="3.316"/>
  </joint>
  <joint name="j2" type="revolute">
    <parent link="lower_frame_link"/>
    <child link="upper_frame_link"/>
    <origin xyz="0.160 0 0.4466" rpy="0 1.5708 0"/>
    <axis xyz="0 -1 0"/>
    <limit lower="-1.222" upper="3.403" effort="1043.28" velocity="3.142"/>
  </joint>
  <joint name="j3" type="revolute">
    <parent link="upper_frame_link"/>
    <child link="arm_link"/>
    <origin xyz="0 0 0.770" rpy="0 0 0"/>
    <axis xyz="0 -1 0"/>
    <limit lower="-1.396" upper="3.141" effort="538.056" velocity="3.316"/>
  </joint>
  <joint name="j4" type="revolute">
    <parent link="arm_link"/>
    <child link="wrist_body_link"/>
    <origin xyz="0 0 0.140" rpy="0 0 0"/>
    <axis xyz="1 0 0"/>
    <limit lower="-3.403" upper="3.403" effort="44.91" velocity="6.632"/>
  </joint>
  <joint name="j5" type="revolute">
    <parent link="wrist_body_link"/>
    <child link="wrist_holder_link"/>
    <origin xyz="0.8 0 0" rpy="0 0 0"/>
    <axis xyz="0 -1 0"/>
    <limit lower="-2.356" upper="2.356" effort="43.52" velocity="6.632"/>
  </joint>
  <joint name="j6" type="revolute">
    <parent link="wrist_holder_link"/>
    <child link="flange_link"/>
    <origin xyz="0.112 0 0" rpy="0 0 0"/>
    <axis xyz="1 0 0"/>
    <limit lower="-6.283" upper="6.283" effort="25.6" velocity="10.472"/>
  </joint>

  <joint name="joint_motor_s" type="fixed">
    <parent link="lower_frame_link"/>
    <child link="motor_s"/>
    <origin xyz="0 0 0" rpy="0 0 0"/>
    <axis xyz="1 0 0"/>
  </joint>
  <joint name="joint_motor_h" type="fixed">
    <parent link="lower_frame_link"/>
    <child link="motor_h"/>
    <origin xyz="0 0 0" rpy="0 0 0"/>
    <axis xyz="1 0 0"/>
  </joint>
  <joint name="joint_motor_v" type="fixed">
    <parent link="upper_frame_link"/>
    <child link="motor_v"/>
    <origin xyz="-0.16 0 -0.4466" rpy="0 0 0"/>
    <axis xyz="1 0 0"/>
  </joint>

  <link name="base"/>
  <joint name="base_link-base" type="fixed">
    <origin xyz="0 0 0" rpy="0 0 0"/>
    <parent link="base_link"/>
    <child link="base"/>
  </joint>
  <link name="flange"/>
  <joint name="flange_link-flange" type="fixed">
    <origin xyz="0 0 0" rpy="0 0 0"/>
    <parent link="flange_link"/>
    <child link="flange"/>
  </joint>
  <link name="tool0"/>
  <joint name="flange-tool0" type="fixed">
    <origin xyz="0 0 0" rpy="0 1.5708 0"/>
    <parent link="flange"/>
    <child link="tool0"/>
  </joint>

  <link name="world"/>
  <joint name="world_joint" type="fixed">
    <parent link="world"/>
    <child link="base_link"/>
    <origin xyz="0 0 0" rpy="0 0 0"/>
  </joint>
</robot>
